{
 "cells": [
  {
   "cell_type": "code",
   "execution_count": 1,
   "metadata": {},
   "outputs": [
    {
     "name": "stdout",
     "output_type": "stream",
     "text": [
      "Requirement already satisfied: pyodbc in c:\\users\\ladislau andré\\anaconda3\\lib\\site-packages (5.1.0)\n",
      "Note: you may need to restart the kernel to use updated packages.\n"
     ]
    }
   ],
   "source": [
    "%pip install pyodbc\n"
   ]
  },
  {
   "cell_type": "code",
   "execution_count": 2,
   "metadata": {},
   "outputs": [],
   "source": [
    "import pyodbc"
   ]
  },
  {
   "cell_type": "code",
   "execution_count": 13,
   "metadata": {},
   "outputs": [
    {
     "name": "stderr",
     "output_type": "stream",
     "text": [
      "<>:2: SyntaxWarning: invalid escape sequence '\\S'\n",
      "<>:2: SyntaxWarning: invalid escape sequence '\\S'\n",
      "C:\\Users\\Ladislau André\\AppData\\Local\\Temp\\ipykernel_11168\\963451620.py:2: SyntaxWarning: invalid escape sequence '\\S'\n",
      "  server = 'Ladislau\\SQLEXPRESS'\n"
     ]
    }
   ],
   "source": [
    "# Define connection parameters\n",
    "server = 'Ladislau\\SQLEXPRESS'\n",
    "database = 'NORTHWND'\n",
    "username = 'novo_usuario'\n",
    "password = 'SenhaForte123!'\n",
    "driver = '{ODBC Driver 18 for SQL Server}'\n"
   ]
  },
  {
   "cell_type": "code",
   "execution_count": 15,
   "metadata": {},
   "outputs": [],
   "source": [
    "conn_str = (\n",
    "    f'DRIVER={driver};'\n",
    "    f'SERVER={server};'\n",
    "    f'DATABASE={database};'\n",
    "    f'UID={username};'\n",
    "    f'PWD={password}'\n",
    ")"
   ]
  },
  {
   "cell_type": "code",
   "execution_count": 16,
   "metadata": {},
   "outputs": [
    {
     "name": "stdout",
     "output_type": "stream",
     "text": [
      "Connection failed: ('08001', '[08001] [Microsoft][ODBC Driver 18 for SQL Server]SSL Provider: A cadeia de certificado foi emitida por uma autoridade não fidedigna.\\r\\n (-2146893019) (SQLDriverConnect); [08001] [Microsoft][ODBC Driver 18 for SQL Server]Client unable to establish connection. For solutions related to encryption errors, see https://go.microsoft.com/fwlink/?linkid=2226722 (-2146893019)')\n"
     ]
    }
   ],
   "source": [
    "# Connect and query\n",
    "try:\n",
    "    conn = pyodbc.connect(conn_str)\n",
    "    cursor = conn.cursor()\n",
    "    cursor.execute(\"SELECT name FROM sys.tables\")\n",
    "    for row in cursor.fetchall():\n",
    "        print(row)\n",
    "    cursor.close()\n",
    "    conn.close()\n",
    "except Exception as e:\n",
    "    print(\"Connection failed:\", e)"
   ]
  }
 ],
 "metadata": {
  "kernelspec": {
   "display_name": "base",
   "language": "python",
   "name": "python3"
  },
  "language_info": {
   "codemirror_mode": {
    "name": "ipython",
    "version": 3
   },
   "file_extension": ".py",
   "mimetype": "text/x-python",
   "name": "python",
   "nbconvert_exporter": "python",
   "pygments_lexer": "ipython3",
   "version": "3.12.7"
  }
 },
 "nbformat": 4,
 "nbformat_minor": 2
}
